<?xml version="1.0" encoding="UTF-8"?>
<sdf version="1.7">
  <model name="stair_climber">
    <link name="base_link">
      <inertial>
        <pose>-0.061099 -2e-06 -0.025087 0 -0 0</pose>
        <mass>3.24079</mass>
        <inertia>
          <ixx>0.0672182</ixx>
          <ixy>-1.34361e-07</ixy>
          <ixz>-0.0127204</ixz>
          <iyy>0.066088</iyy>
          <iyz>-1.64436e-07</iyz>
          <izz>0.125422</izz>
        </inertia>
      </inertial>
      <!-- <collision name="base_link_collision">
        <pose>0 0 0 0 -0 0</pose>
        <geometry>
          <mesh>
            <scale>1 1 1</scale>
            <uri>model://stair_climber/meshes/base_link.STL</uri>
          </mesh>
        </geometry>
      </collision> -->
      <collision name="base_link_fixed_joint_lump__lifter_base_collision_3">
        <pose>0.14057 0.17875 -0.026998 -1.5708 0 1.5708</pose>
        <geometry>
          <mesh>
            <scale>1 1 1</scale>
            <uri>model://stair_climber/meshes/lifter_base.STL</uri>
          </mesh>
        </geometry>
      </collision>
      <!-- <collision name="base_link_fixed_joint_lump__front_proximity_collision_1">
        <pose>0.35767 0 0.09975 0 1.5708 0</pose>
        <geometry>
          <mesh>
            <scale>1 1 1</scale>
            <uri>model://stair_climber/meshes/front_proximity.STL</uri>
          </mesh>
        </geometry>
      </collision>
      <collision name="base_link_fixed_joint_lump__kinect_rod_collision_2">
        <pose>0.32265 0 0.19023 1.5708 -0 0</pose>
        <geometry>
          <mesh>
            <scale>1 1 1</scale>
            <uri>model://stair_climber/meshes/kinect_rod.STL</uri>
          </mesh>
        </geometry>
      </collision>
      <collision name="base_link_fixed_joint_lump__lifter_base_imu_collision_4">
        <pose>0.122341 -0 -0.0336 1.5708 -7e-06 -1.57079</pose>
        <geometry>
          <mesh>
            <scale>1 1 1</scale>
            <uri>model://stair_climber/meshes/lifter_base_imu.STL</uri>
          </mesh>
        </geometry>
      </collision>
      <collision name="base_link_fixed_joint_lump__rear_proximity_collision_5">
        <pose>-0.348369 -2e-06 -0.036601 -3.14159 1.5708 0</pose>
        <geometry>
          <mesh>
            <scale>1 1 1</scale>
            <uri>model://stair_climber/meshes/rear_proximity.STL</uri>
          </mesh>
        </geometry>
      </collision> -->
      <visual name="base_link_visual">
        <pose>0 0 0 0 -0 0</pose>
        <geometry>
          <mesh>
            <scale>1 1 1</scale>
            <uri>model://stair_climber/meshes/base_link.STL</uri>
          </mesh>
        </geometry>
        <material>
          <script>
            <name>Gazebo/DarkGray</name>
            <uri>file://media/materials/scripts/gazebo.material</uri>
          </script>
        </material>
      </visual>
      <visual name='base_link_fixed_joint_lump__left_belt_visual_1'>
        <pose>-0.004278 0.255 -0.008295 -1.5708 0 0</pose>
        <geometry>
          <mesh>
            <scale>1 1 1</scale>
            <uri>model://stair_climber/meshes/belt.STL</uri>
          </mesh>
        </geometry>
        <material>
          <script>
            <name>Gazebo/DarkGray</name>
            <uri>file://media/materials/scripts/gazebo.material</uri>
          </script>
        </material>
      </visual>
      <visual name='base_link_fixed_joint_lump__right_belt_joint_visual_2'>
        <pose>-0.004278 -0.255 -0.008295 -1.5708 0 0</pose>
        <geometry>
          <mesh>
            <scale>1 1 1</scale>
            <uri>model://stair_climber/meshes/belt.STL</uri>
          </mesh>
        </geometry>
        <material>
          <script>
            <name>Gazebo/DarkGray</name>
            <uri>file://media/materials/scripts/gazebo.material</uri>
          </script>
        </material>
      </visual>
      <visual name="base_link_fixed_joint_lump__lifter_base_visual_3">
        <pose>0.14057 0.17875 -0.026998 -1.5708 0 1.5708</pose>
        <geometry>
          <mesh>
            <scale>1 1 1</scale>
            <uri>model://stair_climber/meshes/lifter_base.STL</uri>
          </mesh>
        </geometry>
        <material>
          <script>
            <name>Gazebo/Gold</name>
            <uri>file://media/materials/scripts/gazebo.material</uri>
          </script>
        </material>
      </visual>
      <!-- <visual name="base_link_fixed_joint_lump__front_proximity_visual_1">
        <pose>0.35767 0 0.09975 0 1.5708 0</pose>
        <geometry>
          <mesh>
            <scale>1 1 1</scale>
            <uri>model://stair_climber/meshes/front_proximity.STL</uri>
          </mesh>
        </geometry>
        <material>
          <script>
            <name>Gazebo/Blue</name>
            <uri>file://media/materials/scripts/gazebo.material</uri>
          </script>
        </material>
      </visual>
      <visual name="base_link_fixed_joint_lump__kinect_rod_visual_2">
        <pose>0.32265 0 0.19023 1.5708 -0 0</pose>
        <geometry>
          <mesh>
            <scale>1 1 1</scale>
            <uri>model://stair_climber/meshes/kinect_rod.STL</uri>
          </mesh>
        </geometry>
        <material>
          <script>
            <name>Gazebo/DarkGray</name>
            <uri>file://media/materials/scripts/gazebo.material</uri>
          </script>
        </material>
      </visual>
      <visual name="base_link_fixed_joint_lump__lifter_base_imu_visual_4">
        <pose>0.122341 -0 -0.0336 1.5708 -7e-06 -1.57079</pose>
        <geometry>
          <mesh>
            <scale>1 1 1</scale>
            <uri>model://stair_climber/meshes/lifter_base_imu.STL</uri>
          </mesh>
        </geometry>
        <material>
          <script>
            <name>Gazebo/Red</name>
            <uri>file://media/materials/scripts/gazebo.material</uri>
          </script>
        </material>
      </visual>
      <visual name="base_link_fixed_joint_lump__rear_proximity_visual_5">
        <pose>-0.348369 -2e-06 -0.036601 -3.14159 1.5708 0</pose>
        <geometry>
          <mesh>
            <scale>1 1 1</scale>
            <uri>model://stair_climber/meshes/rear_proximity.STL</uri>
          </mesh>
        </geometry>
        <material>
          <script>
            <name>Gazebo/Blue</name>
            <uri>file://media/materials/scripts/gazebo.material</uri>
          </script>
        </material>
      </visual> -->
      <velocity_decay />
      <gravity>1</gravity>
      <velocity_decay />
    </link>
    <joint name="front_left_large_wheel_joint" type="revolute">
      <pose relative_to="base_link">0.30118 0.255 0.0844 0 -0 0</pose>
      <parent>base_link</parent>
      <child>front_left_large_wheel</child>
      <axis>
        <xyz>0 1 0</xyz>
        <limit>
          <lower>-1e+16</lower>
          <upper>1e+16</upper>
        </limit>
        <dynamics>
          <spring_reference>0</spring_reference>
          <spring_stiffness>0</spring_stiffness>
        </dynamics>
      </axis>
    </joint>
    <link name="front_left_large_wheel">
      <pose relative_to="front_left_large_wheel_joint">0 0 0 0 -0 0</pose>
      <inertial>
        <pose>-0 -1e-06 -0 0 -0 0</pose>
        <mass>0.78039</mass>
        <inertia>
          <ixx>0.0017349</ixx>
          <ixy>-2.7297e-19</ixy>
          <ixz>-1.339e-20</ixz>
          <iyy>0.0028684</iyy>
          <iyz>4.6049e-19</iyz>
          <izz>0.0017349</izz>
        </inertia>
      </inertial>
      <collision name="front_left_large_wheel_collision">
        <pose>0 0 0 0 -0 0</pose>
        <geometry>
          <mesh>
            <scale>1.1 1 1.1</scale>
            <uri>model://stair_climber/meshes/large_wheel.STL</uri>
          </mesh>
        </geometry>
        <surface>
          <contact>
            <ode />
          </contact>
          <friction>
            <ode />
          </friction>
        </surface>
      </collision>
      <visual name="front_left_large_wheel_visual">
        <pose>0 0 0 0 -0 0</pose>
        <geometry>
          <mesh>
            <scale>1 1 1</scale>
            <uri>model://stair_climber/meshes/large_wheel.STL</uri>
          </mesh>
        </geometry>
        <material>
          <script>
            <name>Gazebo/Red</name>
            <uri>file://media/materials/scripts/gazebo.material</uri>
          </script>
        </material>
      </visual>
      <gravity>1</gravity>
      <velocity_decay />
    </link>
    <joint name="front_left_small_wheel_joint" type="revolute">
      <pose relative_to="base_link">0.18654 0.255 -0.0656 0 -0 0</pose>
      <parent>base_link</parent>
      <child>front_left_small_wheel</child>
      <axis>
        <xyz>0 1 0</xyz>
        <limit>
          <lower>-1e+16</lower>
          <upper>1e+16</upper>
        </limit>
        <dynamics>
          <spring_reference>0</spring_reference>
          <spring_stiffness>0</spring_stiffness>
        </dynamics>
      </axis>
    </joint>
    <link name="front_left_small_wheel">
      <pose relative_to="front_left_small_wheel_joint">0 0 0 0 -0 0</pose>
      <inertial>
        <pose>-0 -0 0 0 -0 0</pose>
        <mass>0.31269</mass>
        <inertia>
          <ixx>0.0003624</ixx>
          <ixy>-2.8909e-20</ixy>
          <ixz>9.015e-21</ixz>
          <iyy>0.00050138</iyy>
          <iyz>1.2006e-19</iyz>
          <izz>0.0003624</izz>
        </inertia>
      </inertial>
      <collision name="front_left_small_wheel_collision">
        <pose>0 0 0 0 -0 0</pose>
        <geometry>
          <mesh>
            <scale>1.1 1 1.1</scale>
            <uri>model://stair_climber/meshes/small_wheel.STL</uri>
          </mesh>
        </geometry>
        <surface>
          <contact>
            <ode />
          </contact>
          <friction>
            <ode />
          </friction>
        </surface>
      </collision>
      <visual name="front_left_small_wheel_visual">
        <pose>0 0 0 0 -0 0</pose>
        <geometry>
          <mesh>
            <scale>1 1 1</scale>
            <uri>model://stair_climber/meshes/small_wheel.STL</uri>
          </mesh>
        </geometry>
        <material>
          <script>
            <name>Gazebo/Red</name>
            <uri>file://media/materials/scripts/gazebo.material</uri>
          </script>
        </material>
      </visual>
      <gravity>1</gravity>
      <velocity_decay />
    </link>
    <joint name="front_right_large_wheel_joint" type="revolute">
      <pose relative_to="base_link">0.30118 -0.255 0.0844 0 -0 0</pose>
      <parent>base_link</parent>
      <child>front_right_large_wheel</child>
      <axis>
        <xyz>0 1 0</xyz>
        <limit>
          <lower>-1e+16</lower>
          <upper>1e+16</upper>
        </limit>
        <dynamics>
          <spring_reference>0</spring_reference>
          <spring_stiffness>0</spring_stiffness>
        </dynamics>
      </axis>
    </joint>
    <link name="front_right_large_wheel">
      <pose relative_to="front_right_large_wheel_joint">0 0 0 0 -0 0</pose>
      <inertial>
        <pose>0 -1e-06 -0 0 -0 0</pose>
        <mass>0.78039</mass>
        <inertia>
          <ixx>0.0017349</ixx>
          <ixy>5.4823e-19</ixy>
          <ixz>-1.613e-20</ixz>
          <iyy>0.0028684</iyy>
          <iyz>-5.7522e-19</iyz>
          <izz>0.0017349</izz>
        </inertia>
      </inertial>
      <collision name="front_right_large_wheel_collision">
        <pose>0 0 0 0 -0 0</pose>
        <geometry>
          <mesh>
            <scale>1.1 1 1.1</scale>
            <uri>model://stair_climber/meshes/large_wheel.STL</uri>
          </mesh>
        </geometry>
        <surface>
          <contact>
            <ode />
          </contact>
          <friction>
            <ode />
          </friction>
        </surface>
      </collision>
      <visual name="front_right_large_wheel_visual">
        <pose>0 0 0 0 -0 0</pose>
        <geometry>
          <mesh>
            <scale>1 1 1</scale>
            <uri>model://stair_climber/meshes/large_wheel.STL</uri>
          </mesh>
        </geometry>
        <material>
          <script>
            <name>Gazebo/Red</name>
            <uri>file://media/materials/scripts/gazebo.material</uri>
          </script>
        </material>
      </visual>
      <gravity>1</gravity>
      <velocity_decay />
    </link>
    <joint name="front_right_small_wheel_joint" type="revolute">
      <pose relative_to="base_link">0.18654 -0.255 -0.0656 0 -0 0</pose>
      <parent>base_link</parent>
      <child>front_right_small_wheel</child>
      <axis>
        <xyz>0 1 0</xyz>
        <limit>
          <lower>-1e+16</lower>
          <upper>1e+16</upper>
        </limit>
        <dynamics>
          <spring_reference>0</spring_reference>
          <spring_stiffness>0</spring_stiffness>
        </dynamics>
      </axis>
    </joint>
    <link name="front_right_small_wheel">
      <pose relative_to="front_right_small_wheel_joint">0 0 0 0 -0 0</pose>
      <inertial>
        <pose>0 -0 -0 0 -0 0</pose>
        <mass>0.31269</mass>
        <inertia>
          <ixx>0.0003624</ixx>
          <ixy>7.0996e-20</ixy>
          <ixz>9.9779e-21</ixz>
          <iyy>0.00050138</iyy>
          <iyz>4.582e-21</iyz>
          <izz>0.0003624</izz>
        </inertia>
      </inertial>
      <collision name="front_right_small_wheel_collision">
        <pose>0 0 0 0 -0 0</pose>
        <geometry>
          <mesh>
            <scale>1.1 1 1.1</scale>
            <uri>model://stair_climber/meshes/small_wheel.STL</uri>
          </mesh>
        </geometry>
        <surface>
          <contact>
            <ode />
          </contact>
          <friction>
            <ode />
          </friction>
        </surface>
      </collision>
      <visual name="front_right_small_wheel_visual">
        <pose>0 0 0 0 -0 0</pose>
        <geometry>
          <mesh>
            <scale>1 1 1</scale>
            <uri>model://stair_climber/meshes/small_wheel.STL</uri>
          </mesh>
        </geometry>
        <material>
          <script>
            <name>Gazebo/Red</name>
            <uri>file://media/materials/scripts/gazebo.material</uri>
          </script>
        </material>
      </visual>
      <gravity>1</gravity>
      <velocity_decay />
    </link>
    <joint name="lifter_joint" type="revolute">
      <pose relative_to="base_link">0.076558 -0 0.0169 4e-06 -0.0035 4e-06</pose>
      <parent>base_link</parent>
      <child>lifter</child>
      <axis>
        <xyz>0 1 0</xyz>
        <limit>
          <lower>0</lower>
          <upper>0.5</upper>
        </limit>
        <dynamics>
          <spring_reference>0</spring_reference>
          <spring_stiffness>0</spring_stiffness>
        </dynamics>
      </axis>
    </joint>
    <link name="lifter">
      <pose relative_to="lifter_joint">0 0 0 0 -0 0</pose>
      <inertial>
        <pose>-0.233715 -2e-06 -0.001076 0 -0 0</pose>
        <mass>1.26035</mass>
        <inertia>
          <ixx>0.0194267</ixx>
          <ixy>4.54521e-07</ixy>
          <ixz>-5.31236e-05</ixz>
          <iyy>0.0308007</iyy>
          <iyz>1.13048e-08</iyz>
          <izz>0.0501238</izz>
        </inertia>
      </inertial>
      <collision name="lifter_collision">
        <pose>0 0 0 0 -0 0</pose>
        <geometry>
          <mesh>
            <scale>1 1 1</scale>
            <uri>model://stair_climber/meshes/lifter.STL</uri>
          </mesh>
        </geometry>
        <surface>
          <contact>
            <ode />
          </contact>
          <friction>
            <ode />
          </friction>
        </surface>
      </collision>
      <collision name="lifter_imu_collision_1">
        <pose>7.1e-05 -0.018 0 1.5708 0 -1.5708</pose>
        <geometry>
          <mesh>
            <scale>1 1 1</scale>
            <uri>model://stair_climber/meshes/lifter_imu.STL</uri>
          </mesh>
        </geometry>
        <surface>
          <contact>
            <ode />
          </contact>
          <friction>
            <ode />
          </friction>
        </surface>
      </collision>
      <visual name="lifter_visual">
        <pose>0 0 0 0 -0 0</pose>
        <geometry>
          <mesh>
            <scale>1 1 1</scale>
            <uri>model://stair_climber/meshes/lifter.STL</uri>
          </mesh>
        </geometry>
        <material>
          <script>
            <name>Gazebo/Gray</name>
            <uri>file://media/materials/scripts/gazebo.material</uri>
          </script>
        </material>
      </visual>
      <visual name="lifter_imu_visual_1">
        <pose>7.1e-05 -0.018 0 1.5708 0 -1.5708</pose>
        <geometry>
          <mesh>
            <scale>1 1 1</scale>
            <uri>model://stair_climber/meshes/lifter_imu.STL</uri>
          </mesh>
        </geometry>
        <material>
          <script>
            <name>Gazebo/Red</name>
            <uri>file://media/materials/scripts/gazebo.material</uri>
          </script>
        </material>
      </visual>
      <gravity>1</gravity>
      <velocity_decay />
    </link>
    <joint name="rear_left_small_wheel_joint" type="revolute">
      <pose relative_to="base_link">-0.36346 0.255 -0.0656 0 -0 0</pose>
      <parent>base_link</parent>
      <child>rear_left_small_wheel</child>
      <axis>
        <xyz>0 1 0</xyz>
        <limit>
          <lower>-1e+16</lower>
          <upper>1e+16</upper>
        </limit>
        <dynamics>
          <spring_reference>0</spring_reference>
          <spring_stiffness>0</spring_stiffness>
        </dynamics>
      </axis>
    </joint>
    <link name="rear_left_small_wheel">
      <pose relative_to="rear_left_small_wheel_joint">0 0 0 0 -0 0</pose>
      <inertial>
        <pose>-0 -0 0 0 -0 0</pose>
        <mass>0.31269</mass>
        <inertia>
          <ixx>0.0003624</ixx>
          <ixy>-5.2962e-20</ixy>
          <ixz>9.9779e-21</ixz>
          <iyy>0.00050138</iyy>
          <iyz>5.0804e-20</iyz>
          <izz>0.0003624</izz>
        </inertia>
      </inertial>
      <collision name="rear_left_small_wheel_collision">
        <pose>0 0 0 0 -0 0</pose>
        <geometry>
          <mesh>
            <scale>1.1 1 1.1</scale>
            <uri>model://stair_climber/meshes/small_wheel.STL</uri>
          </mesh>
        </geometry>
        <surface>
          <contact>
            <ode />
          </contact>
          <friction>
            <ode />
          </friction>
        </surface>
      </collision>
      <visual name="rear_left_small_wheel_visual">
        <pose>0 0 0 0 -0 0</pose>
        <geometry>
          <mesh>
            <scale>1 1 1</scale>
            <uri>model://stair_climber/meshes/small_wheel.STL</uri>
          </mesh>
        </geometry>
        <material>
          <script>
            <name>Gazebo/Red</name>
            <uri>file://media/materials/scripts/gazebo.material</uri>
          </script>
        </material>
      </visual>
      <gravity>1</gravity>
      <velocity_decay />
    </link>
    <joint name="rear_right_small_wheel_joint" type="revolute">
      <pose relative_to="base_link">-0.36346 -0.255 -0.0656 0 -0 0</pose>
      <parent>base_link</parent>
      <child>rear_right_small_wheel</child>
      <axis>
        <xyz>0 1 0</xyz>
        <limit>
          <lower>-1e+16</lower>
          <upper>1e+16</upper>
        </limit>
        <dynamics>
          <spring_reference>0</spring_reference>
          <spring_stiffness>0</spring_stiffness>
        </dynamics>
      </axis>
    </joint>
    <link name="rear_right_small_wheel">
      <pose relative_to="rear_right_small_wheel_joint">0 0 0 0 -0 0</pose>
      <inertial>
        <pose>-0 -0 0 0 -0 0</pose>
        <mass>0.31269</mass>
        <inertia>
          <ixx>0.0003624</ixx>
          <ixy>5.2766e-20</ixy>
          <ixz>8.4875e-21</ixz>
          <iyy>0.00050138</iyy>
          <iyz>3.9357e-21</iyz>
          <izz>0.0003624</izz>
        </inertia>
      </inertial>
      <collision name="rear_right_small_wheel_collision">
        <pose>0 0 0 0 -0 0</pose>
        <geometry>
          <mesh>
            <scale>1.1 1 1.1</scale>
            <uri>model://stair_climber/meshes/small_wheel.STL</uri>
          </mesh>
        </geometry>
        <surface>
          <contact>
            <ode />
          </contact>
          <friction>
            <ode />
          </friction>
        </surface>
      </collision>
      <visual name="rear_right_small_wheel_visual">
        <pose>0 0 0 0 -0 0</pose>
        <geometry>
          <mesh>
            <scale>1 1 1</scale>
            <uri>model://stair_climber/meshes/small_wheel.STL</uri>
          </mesh>
        </geometry>
        <material>
          <script>
            <name>Gazebo/Red</name>
            <uri>file://media/materials/scripts/gazebo.material</uri>
          </script>
        </material>
      </visual>
      <gravity>1</gravity>
      <velocity_decay />
    </link>
    <joint name="kinect_joint" type="fixed">
      <pose relative_to="base_link">0.36 0 0.14 0 -0 0</pose>
      <parent>base_link</parent>
      <child>kinect</child>
    </joint>
    <link name="kinect">
      <pose relative_to="kinect_joint">0 0 0 0 -0 0</pose>
      <inertial>
        <mass>0.1</mass>
      </inertial>
      <collision name="kinect_collision">
        <geometry>
          <box>
            <size>0.073000 0.276000 0.072000</size>
          </box>
        </geometry>
      </collision>
      <visual name="kinect_visual">
        <geometry>
          <mesh>
            <scale>0.75 0.75 0.75</scale>
            <uri>model://kinect/meshes/kinect.dae</uri>
          </mesh>
        </geometry>
      </visual>
      <sensor name="kinect" type="depth">
        <update_rate>20</update_rate>
        <camera>
          <horizontal_fov>1.047198</horizontal_fov>
          <image>
            <width>640</width>
            <height>480</height>
            <format>R8G8B8</format>
          </image>
          <clip>
            <near>0.05</near>
            <far>3</far>
          </clip>
        </camera>
        <plugin name="kinect_controller" filename="libgazebo_ros_openni_kinect.so">
          <baseline>0.2</baseline>
          <alwaysOn>true</alwaysOn>
          <updateRate>1.0</updateRate>
          <cameraName>kinect</cameraName>
          <imageTopicName>/kinect/color/image_raw</imageTopicName>
          <cameraInfoTopicName>/kinect/color/camera_info</cameraInfoTopicName>
          <depthImageTopicName>/kinect/depth/image_raw</depthImageTopicName>
          <depthImageInfoTopicName>/kinect/depth/camera_info</depthImageInfoTopicName>
          <pointCloudTopicName>/kinect/depth/points</pointCloudTopicName>
          <frameName>base_link</frameName>
          <pointCloudCutoff>0.5</pointCloudCutoff>
          <pointCloudCutoffMax>3.0</pointCloudCutoffMax>
          <distortionK1>0.00000001</distortionK1>
          <distortionK2>0.00000001</distortionK2>
          <distortionK3>0.00000001</distortionK3>
          <distortionT1>0.00000001</distortionT1>
          <distortionT2>0.00000001</distortionT2>
          <CxPrime>0</CxPrime>
          <Cx>0</Cx>
          <Cy>0</Cy>
          <focalLength>0</focalLength>
          <hackBaseline>0</hackBaseline>
        </plugin>
      </sensor>
    </link>
    <plugin name="skid_steer_drive_controller" filename="libgazebo_ros_skid_steer_drive.so">
      <updateRate>100.0</updateRate>
      <robotNamespace>/</robotNamespace>
      <leftFrontJoint>front_left_small_wheel_joint</leftFrontJoint>
      <rightFrontJoint>front_right_small_wheel_joint</rightFrontJoint>
      <leftRearJoint>rear_left_small_wheel_joint</leftRearJoint>
      <rightRearJoint>rear_right_small_wheel_joint</rightRearJoint>
      <wheelSeparation>0.51</wheelSeparation>
      <wheelDiameter>0.11</wheelDiameter>
      <robotBaseFrame>base_link</robotBaseFrame>
      <torque>5</torque>
      <topicName>cmd_vel</topicName>
      <broadcastTF>false</broadcastTF>
    </plugin>
  </model>
</sdf>
