<?xml version="1.0" encoding="UTF-8"?>
<!-- This URDF was automatically created by SolidWorks to URDF Exporter! Originally created by Stephen Brawner (brawner@gmail.com)
Commit Version: 1.6.0-1-g15f4949  Build Version: 1.6.7594.29634
For more information, please see http://wiki.ros.org/sw_urdf_exporter -->
<robot name="stair_climber">
  <gazebo reference="base_link">
    <material>Gazebo/DarkGray</material>
  </gazebo>
  <gazebo reference="kinect">
    <material>Gazebo/DarkGray</material>
  </gazebo>
  <gazebo reference="left_belt">
    <material>Gazebo/DarkGray</material>
  </gazebo>
  <gazebo reference="right_belt">
    <material>Gazebo/DarkGray</material>
  </gazebo>
  <gazebo reference="bottom_camera">
    <material>Gazebo/Gray</material>
  </gazebo>
  <gazebo reference="lifter_base">
    <material>Gazebo/Gray</material>
  </gazebo>
  <gazebo reference="lifter">
    <material>Gazebo/LightGray</material>
  </gazebo>
  <gazebo reference="front_left_large_wheel">
    <material>Gazebo/Red</material>
  </gazebo>
  <gazebo reference="front_right_large_wheel">
    <material>Gazebo/Red</material>
  </gazebo>
  <gazebo reference="front_left_small_wheel">
    <material>Gazebo/Red</material>
  </gazebo>
  <gazebo reference="front_right_small_wheel">
    <material>Gazebo/Red</material>
  </gazebo>
  <gazebo reference="rear_left_small_wheel">
    <material>Gazebo/Red</material>
  </gazebo>
  <gazebo reference="rear_right_small_wheel">
    <material>Gazebo/Red</material>
  </gazebo>
  <gazebo reference="lifter_imu">
    <material>Gazebo/Red</material>
  </gazebo>
  <gazebo reference="lifter_base_imu">
    <material>Gazebo/Red</material>
  </gazebo>


  <link name="base_link">
    <inertial>
      <origin xyz="0.29928 -2.6383E-08 0.087595" rpy="0 0 0" />
      <mass value="0.22457" />
      <inertia ixx="0.00043675" ixy="-1.7875E-10" ixz="-1.6661E-05" iyy="0.00014803" iyz="1.1703E-09" izz="0.00051388" />
    </inertial>
    <visual>
      <origin xyz="0 0 0" rpy="0 0 0" />
      <geometry>
        <mesh filename="package://amazon_hackon/models/stair_climber/meshes/base_link.STL" />
      </geometry>
      <material name="">
        <color rgba="0.75294 0.75294 0.75294 1" />
      </material>
    </visual>
    <!-- <collision>
      <origin xyz="0 0 0" rpy="0 0 0" />
      <geometry>
        <mesh filename="package://amazon_hackon/models/stair_climber/meshes/base_link.STL" />
      </geometry>
    </collision> -->
  </link>
  <link name="front_left_large_wheel">
    <inertial>
      <origin xyz="-8.3267E-17 -6.7342E-07 -5.5511E-17" rpy="0 0 0" />
      <mass value="0.78039" />
      <inertia ixx="0.0017349" ixy="-2.7297E-19" ixz="-1.339E-20" iyy="0.0028684" iyz="4.6049E-19" izz="0.0017349" />
    </inertial>
    <visual>
      <origin xyz="0 0 0" rpy="0 0 0" />
      <geometry>
        <mesh filename="package://amazon_hackon/models/stair_climber/meshes/large_wheel.STL" />
      </geometry>
      <material name="">
        <color rgba="1 0 0 1" />
      </material>
    </visual>
    <collision>
      <origin xyz="0 0 0" rpy="0 0 0" />
      <geometry>
        <mesh filename="package://amazon_hackon/models/stair_climber/meshes/large_wheel.STL" scale="1.1 1 1.1" />
      </geometry>
    </collision>
  </link>
  <joint name="front_left_large_wheel_joint" type="continuous">
    <origin xyz="0.30118 0.255 0.0844" rpy="0 0 0" />
    <parent link="base_link" />
    <child link="front_left_large_wheel" />
    <axis xyz="0 1 0" />
  </joint>
  <link name="front_right_large_wheel">
    <inertial>
      <origin xyz="0 -6.7342E-07 -2.7756E-17" rpy="0 0 0" />
      <mass value="0.78039" />
      <inertia ixx="0.0017349" ixy="5.4823E-19" ixz="-1.613E-20" iyy="0.0028684" iyz="-5.7522E-19" izz="0.0017349" />
    </inertial>
    <visual>
      <origin xyz="0 0 0" rpy="0 0 0" />
      <geometry>
        <mesh filename="package://amazon_hackon/models/stair_climber/meshes/large_wheel.STL" />
      </geometry>
      <material name="">
        <color rgba="1 0 0 1" />
      </material>
    </visual>
    <collision>
      <origin xyz="0 0 0" rpy="0 0 0" />
      <geometry>
        <mesh filename="package://amazon_hackon/models/stair_climber/meshes/large_wheel.STL" scale="1.1 1 1.1" />
      </geometry>
    </collision>
  </link>
  <joint name="front_right_large_wheel_joint" type="continuous">
    <origin xyz="0.30118 -0.255 0.0844" rpy="0 0 0" />
    <parent link="base_link" />
    <child link="front_right_large_wheel" />
    <axis xyz="0 1 0" />
  </joint>
  <link name="front_left_small_wheel">
    <inertial>
      <origin xyz="-3.8858E-16 -3.8217E-07 4.7184E-16" rpy="0 0 0" />
      <mass value="0.31269" />
      <inertia ixx="0.0003624" ixy="-2.8909E-20" ixz="9.015E-21" iyy="0.00050138" iyz="1.2006E-19" izz="0.0003624" />
    </inertial>
    <visual>
      <origin xyz="0 0 0" rpy="0 0 0" />
      <geometry>
        <mesh filename="package://amazon_hackon/models/stair_climber/meshes/small_wheel.STL" />
      </geometry>
      <material name="">
        <color rgba="1 0 0 1" />
      </material>
    </visual>
    <collision>
      <origin xyz="0 0 0" rpy="0 0 0" />
      <geometry>
        <mesh filename="package://amazon_hackon/models/stair_climber/meshes/small_wheel.STL" scale="1.1 1 1.1" />
      </geometry>
    </collision>
  </link>
  <joint name="front_left_small_wheel_joint" type="continuous">
    <origin xyz="0.18654 0.255 -0.0656" rpy="0 0 0" />
    <parent link="base_link" />
    <child link="front_left_small_wheel" />
    <axis xyz="0 1 0" />
  </joint>
  <link name="front_right_small_wheel">
    <inertial>
      <origin xyz="0 -3.8217E-07 -3.4694E-18" rpy="0 0 0" />
      <mass value="0.31269" />
      <inertia ixx="0.0003624" ixy="7.0996E-20" ixz="9.9779E-21" iyy="0.00050138" iyz="4.582E-21" izz="0.0003624" />
    </inertial>
    <visual>
      <origin xyz="0 0 0" rpy="0 0 0" />
      <geometry>
        <mesh filename="package://amazon_hackon/models/stair_climber/meshes/small_wheel.STL" />
      </geometry>
      <material name="">
        <color rgba="1 0 0 1" />
      </material>
    </visual>
    <collision>
      <origin xyz="0 0 0" rpy="0 0 0" />
      <geometry>
        <mesh filename="package://amazon_hackon/models/stair_climber/meshes/small_wheel.STL" scale="1.1 1 1.1" />
      </geometry>
    </collision>
  </link>
  <joint name="front_right_small_wheel_joint" type="continuous">
    <origin xyz="0.18654 -0.255 -0.0656" rpy="0 0 0" />
    <parent link="base_link" />
    <child link="front_right_small_wheel" />
    <axis xyz="0 1 0" />
  </joint>
  <link name="rear_left_small_wheel">
    <inertial>
      <origin xyz="-4.996E-16 -3.8217E-07 4.7878E-16" rpy="0 0 0" />
      <mass value="0.31269" />
      <inertia ixx="0.0003624" ixy="-5.2962E-20" ixz="9.9779E-21" iyy="0.00050138" iyz="5.0804E-20" izz="0.0003624" />
    </inertial>
    <visual>
      <origin xyz="0 0 0" rpy="0 0 0" />
      <geometry>
        <mesh filename="package://amazon_hackon/models/stair_climber/meshes/small_wheel.STL" />
      </geometry>
      <material name="">
        <color rgba="1 0 0 1" />
      </material>
    </visual>
    <collision>
      <origin xyz="0 0 0" rpy="0 0 0" />
      <geometry>
        <mesh filename="package://amazon_hackon/models/stair_climber/meshes/small_wheel.STL" scale="1.1 1 1.1" />
      </geometry>
    </collision>
  </link>
  <joint name="rear_left_small_wheel_joint" type="continuous">
    <origin xyz="-0.36346 0.255 -0.0656" rpy="0 0 0" />
    <parent link="base_link" />
    <child link="rear_left_small_wheel" />
    <axis xyz="0 1 0" />
  </joint>
  <link name="rear_right_small_wheel">
    <inertial>
      <origin xyz="-5.5511E-17 -3.8217E-07 0" rpy="0 0 0" />
      <mass value="0.31269" />
      <inertia ixx="0.0003624" ixy="5.2766E-20" ixz="8.4875E-21" iyy="0.00050138" iyz="3.9357E-21" izz="0.0003624" />
    </inertial>
    <visual>
      <origin xyz="0 0 0" rpy="0 0 0" />
      <geometry>
        <mesh filename="package://amazon_hackon/models/stair_climber/meshes/small_wheel.STL" />
      </geometry>
      <material name="">
        <color rgba="1 0 0 1" />
      </material>
    </visual>
    <collision>
      <origin xyz="0 0 0" rpy="0 0 0" />
      <geometry>
        <mesh filename="package://amazon_hackon/models/stair_climber/meshes/small_wheel.STL" scale="1.1 1 1.1" />
      </geometry>
    </collision>
  </link>
  <joint name="rear_right_small_wheel_joint" type="continuous">
    <origin xyz="-0.36346 -0.255 -0.0656" rpy="0 0 0" />
    <parent link="base_link" />
    <child link="rear_right_small_wheel" />
    <axis xyz="0 1 0" />
  </joint>
  <link name="left_belt">
    <inertial>
      <origin xyz="6.7993E-07 1.9652E-06 1.5014E-06" rpy="0 0 0" />
      <mass value="0.87712" />
      <inertia ixx="0.0070793" ixy="0.0072146" ixz="6.7373E-18" iyy="0.042148" iyz="3.8099E-18" izz="0.048405" />
    </inertial>
    <visual>
      <origin xyz="0 0 0" rpy="0 0 0" />
      <geometry>
        <mesh filename="package://amazon_hackon/models/stair_climber/meshes/belt.STL" />
      </geometry>
    </visual>
  </link>
  <joint name="left_belt_joint" type="fixed">
    <origin xyz="-0.004278 0.255 -0.008295" rpy="-1.5708 0 0" />
    <parent link="base_link" />
    <child link="left_belt" />
    <axis xyz="0 0 0" />
  </joint>
  <link name="right_belt">
    <inertial>
      <origin xyz="6.7993E-07 1.9652E-06 1.5014E-06" rpy="0 0 0" />
      <mass value="0.87712" />
      <inertia ixx="0.0070793" ixy="0.0072146" ixz="6.6615E-18" iyy="0.042148" iyz="3.8282E-18" izz="0.048405" />
    </inertial>
    <visual>
      <origin xyz="0 0 0" rpy="0 0 0" />
      <geometry>
        <mesh filename="package://amazon_hackon/models/stair_climber/meshes/belt.STL" />
      </geometry>
    </visual>
  </link>
  <joint name="right_belt_joint" type="fixed">
    <origin xyz="-0.004278 -0.255 -0.008295" rpy="-1.5708 0 0" />
    <parent link="base_link" />
    <child link="right_belt" />
    <axis xyz="0 0 0" />
  </joint>
  <link name="lifter_base">
    <inertial>
      <origin xyz="-0.17875 0.0077953 0.23116" rpy="0 0 0" />
      <mass value="2.9505" />
      <inertia ixx="0.022818" ixy="4.8744E-19" ixz="-2.4381E-19" iyy="0.085398" iyz="-0.001011" izz="0.063079" />
    </inertial>
    <visual>
      <origin xyz="0 0 0" rpy="0 0 0" />
      <geometry>
        <mesh filename="package://amazon_hackon/models/stair_climber/meshes/lifter_base.STL" />
      </geometry>
      <material name="">
        <color rgba="0.79216 0.81961 0.93333 1" />
      </material>
    </visual>
    <collision>
      <origin xyz="0 0 0" rpy="0 0 0" />
      <geometry>
        <mesh filename="package://amazon_hackon/models/stair_climber/meshes/lifter_base.STL" />
      </geometry>
    </collision>
  </link>
  <joint name="lifter_base_joint" type="fixed">
    <origin xyz="0.14057 0.17875 -0.026998" rpy="-1.5708 0 1.5708" />
    <parent link="base_link" />
    <child link="lifter_base" />
    <axis xyz="0 0 0" />
  </joint>
  <link name="lifter">
    <inertial>
      <origin xyz="-0.23492 -2.1915E-09 -0.0011098" rpy="0 0 0" />
      <mass value="1.2527" />
      <inertia ixx="0.019426" ixy="4.789E-10" ixz="-4.4821E-05" iyy="0.0305" iyz="2.0862E-11" izz="0.049823" />
    </inertial>
    <visual>
      <origin xyz="0 0 0" rpy="0 0 0" />
      <geometry>
        <mesh filename="package://amazon_hackon/models/stair_climber/meshes/lifter.STL" />
      </geometry>
      <material name="">
        <color rgba="0.79216 0.81961 0.93333 1" />
      </material>
    </visual>
    <collision>
      <origin xyz="0 0 0" rpy="0 0 0" />
      <geometry>
        <mesh filename="package://amazon_hackon/models/stair_climber/meshes/lifter.STL" />
      </geometry>
    </collision>
  </link>
  <joint name="lifter_joint" type="continuous">
    <origin xyz="-0.17875 -0.043898 0.064012" rpy="0 1.5673 -1.5708" />
    <parent link="lifter_base" />
    <child link="lifter" />
    <axis xyz="0 1 0" />
  </joint>
  <link name="lifter_imu">
    <inertial>
      <origin xyz="-0.017684 0.0043809 0.036435" rpy="0 0 0" />
      <mass value="0.0076507" />
      <inertia ixx="6.2819E-07" ixy="1.9039E-09" ixz="-2.2873E-08" iyy="1.0276E-06" iyz="1.2547E-08" izz="4.4643E-07" />
    </inertial>
    <visual>
      <origin xyz="0 0 0" rpy="0 0 0" />
      <geometry>
        <mesh filename="package://amazon_hackon/models/stair_climber/meshes/lifter_imu.STL" />
      </geometry>
      <material name="">
        <color rgba="0.79216 0.81961 0.93333 1" />
      </material>
    </visual>
    <collision>
      <origin xyz="0 0 0" rpy="0 0 0" />
      <geometry>
        <mesh filename="package://amazon_hackon/models/stair_climber/meshes/lifter_imu.STL" />
      </geometry>
    </collision>
  </link>
  <joint name="lifter_imu_joint" type="fixed">
    <origin xyz="7.1068E-05 -0.018 0" rpy="1.5708 0 -1.5708" />
    <parent link="lifter" />
    <child link="lifter_imu" />
    <axis xyz="0 0 0" />
  </joint>


  <link name="box">
    <visual>
      <origin xyz="0 0 0" rpy="0 0 0" />
      <geometry>
        <mesh filename="package://amazon_hackon/models/small_box/meshes/small_box.dae" />
      </geometry>
    </visual>
  </link>
  <joint name="box_joint" type="fixed">
    <origin xyz="-0.26 0 0.0713" rpy="0 0 0" />
    <parent link="lifter" />
    <child link="box" />
    <axis xyz="0 0 0" />
  </joint>


  <link name="lifter_base_imu">
    <inertial>
      <origin xyz="0.00031574 0.0023809 0.0025315" rpy="0 0 0" />
      <mass value="0.0076507" />
      <inertia ixx="6.2819E-07" ixy="1.9039E-09" ixz="-2.2873E-08" iyy="1.0276E-06" iyz="1.2547E-08" izz="4.4643E-07" />
    </inertial>
    <visual>
      <origin xyz="0 0 0" rpy="0 0 0" />
      <geometry>
        <mesh filename="package://amazon_hackon/models/stair_climber/meshes/lifter_base_imu.STL" />
      </geometry>
      <material name="">
        <color rgba="0.79216 0.81961 0.93333 1" />
      </material>
    </visual>
    <collision>
      <origin xyz="0 0 0" rpy="0 0 0" />
      <geometry>
        <mesh filename="package://amazon_hackon/models/stair_climber/meshes/lifter_base_imu.STL" />
      </geometry>
    </collision>
  </link>
  <joint name="lifter_base_imu_joint" type="fixed">
    <origin xyz="-0.17875 0.0066015 0.01823" rpy="0 0 3.1416" />
    <parent link="lifter_base" />
    <child link="lifter_base_imu" />
    <axis xyz="0 0 0" />
  </joint>


  <link name="bottom_camera">
    <inertial>
      <origin xyz="0.0062452 3.2017E-05 -0.0014786" rpy="0 0 0" />
      <mass value="0.027653" />
      <inertia ixx="2.3096E-05" ixy="7.8475E-12" ixz="-1.1478E-08" iyy="8.4763E-07" iyz="6.099E-09" izz="2.2578E-05" />
    </inertial>
    <visual>
      <origin xyz="0 0 0" rpy="0 0 0" />
      <geometry>
        <mesh filename="package://amazon_hackon/models/stair_climber/meshes/proximity.STL" />
      </geometry>
      <material name="">
        <color rgba="0.75294 0.75294 0.75294 1" />
      </material>
    </visual>
    <collision>
      <origin xyz="0 0 0" rpy="0 0 0" />
      <geometry>
        <mesh filename="package://amazon_hackon/models/stair_climber/meshes/proximity.STL" />
      </geometry>
    </collision>
  </link>
  <joint name="bottom_camera_joint" type="fixed">
    <origin xyz="0.35767 0 0.09975" rpy="0 1.5708 0" />
    <parent link="base_link" />
    <child link="bottom_camera" />
    <axis xyz="0 0 0" />
  </joint>
  <link name="kinect">
    <inertial>
      <origin xyz="2.945E-06 2.8388E-06 2.5103E-16" rpy="0 0 0" />
      <mass value="0.002763" />
      <inertia ixx="1.4164E-06" ixy="2.5328E-22" ixz="5.0848E-23" iyy="7.0291E-08" iyz="-2.9899E-23" izz="1.4183E-06" />
    </inertial>
    <visual>
      <origin xyz="0 0 0" rpy="0 0 0" />
      <geometry>
        <mesh filename="package://amazon_hackon/models/stair_climber/meshes/kinect.dae" scale="0.75 0.75 0.75" />
      </geometry>
    </visual>
    <collision>
      <origin xyz="0 0 0" rpy="0 0 0" />
      <geometry>
        <box size="0.073000 0.276000 0.072000" />
      </geometry>
    </collision>
  </link>
  <joint name="kinect_joint" type="fixed">
    <origin xyz="0.36 0 0.14" rpy="0 -0 0" />
    <parent link="base_link" />
    <child link="kinect" />
    <axis xyz="0 0 0" />
  </joint>
  <gazebo reference="kinect">
    <sensor name="kinect_sensor" type="depth">
      <update_rate>20</update_rate>
      <camera>
        <horizontal_fov>1.047198</horizontal_fov>
        <image>
          <width>640</width>
          <height>480</height>
          <format>R8G8B8</format>
        </image>
        <clip>
          <near>0.05</near>
          <far>3</far>
        </clip>
      </camera>
      <plugin name="kinect_controller" filename="libgazebo_ros_openni_kinect.so">
        <baseline>0.2</baseline>
        <alwaysOn>true</alwaysOn>
        <updateRate>1.0</updateRate>
        <cameraName>kinect</cameraName>
        <imageTopicName>/kinect/color/image_raw</imageTopicName>
        <cameraInfoTopicName>/kinect/color/camera_info</cameraInfoTopicName>
        <depthImageTopicName>/kinect/depth/image_raw</depthImageTopicName>
        <depthImageInfoTopicName>/kinect/depth/camera_info</depthImageInfoTopicName>
        <pointCloudTopicName>/kinect/depth/points</pointCloudTopicName>
        <frameName>base_link</frameName>
        <pointCloudCutoff>0.5</pointCloudCutoff>
        <pointCloudCutoffMax>3.0</pointCloudCutoffMax>
        <distortionK1>0.00000001</distortionK1>
        <distortionK2>0.00000001</distortionK2>
        <distortionK3>0.00000001</distortionK3>
        <distortionT1>0.00000001</distortionT1>
        <distortionT2>0.00000001</distortionT2>
        <CxPrime>0</CxPrime>
        <Cx>0</Cx>
        <Cy>0</Cy>
        <focalLength>0</focalLength>
        <hackBaseline>0</hackBaseline>
      </plugin>
    </sensor>
  </gazebo>
  <gazebo reference="bottom_camera">
    <sensor type="camera" name="bottom_camera_sensor">
      <update_rate>10</update_rate>
      <camera>
        <horizontal_fov>1.57</horizontal_fov>
        <image>
          <format>R8G8B8</format>
          <width>320</width>
          <height>240</height>
        </image>
        <clip>
          <near>0.02</near>
          <far>5</far>
        </clip>
      </camera>
      <plugin name="bottom_camera_controller" filename="libgazebo_ros_camera.so">
        <cameraName>bottom_camera</cameraName>
        <imageTopicName>bottom_camera/image</imageTopicName>
        <cameraInfoTopicName>bottom_camera/camera_info</cameraInfoTopicName>
        <frameName>base_link</frameName>
      </plugin>
    </sensor>
  </gazebo>
  <gazebo>
    <plugin name="skid_steer_drive_controller" filename="libgazebo_ros_skid_steer_drive.so">
      <updateRate>10.0</updateRate>
      <robotNamespace>/</robotNamespace>
      <leftFrontJoint>front_left_small_wheel_joint</leftFrontJoint>
      <rightFrontJoint>front_right_small_wheel_joint</rightFrontJoint>
      <leftRearJoint>rear_left_small_wheel_joint</leftRearJoint>
      <rightRearJoint>rear_right_small_wheel_joint</rightRearJoint>
      <wheelSeparation>0.51</wheelSeparation>
      <wheelDiameter>0.11</wheelDiameter>
      <robotBaseFrame>base_link</robotBaseFrame>
      <torque>5</torque>
      <topicName>cmd_vel</topicName>
      <broadcastTF>false</broadcastTF>
    </plugin>
  </gazebo>
  <gazebo>
    <plugin name="differential_drive_controller" filename="libgazebo_ros_diff_drive.so">
      <updateRate>10</updateRate>
      <leftJoint>front_left_large_wheel_joint</leftJoint>
      <rightJoint>front_right_large_wheel_joint</rightJoint>
      <wheelSeparation>0.51</wheelSeparation>
      <wheelDiameter>0.15</wheelDiameter>
      <wheelAcceleration>1.0</wheelAcceleration>
      <wheelTorque>5</wheelTorque>
      <commandTopic>cmd_vel</commandTopic>
      <odometryTopic>odom</odometryTopic>
      <odometryFrame>odom</odometryFrame>
      <robotBaseFrame>base_footprint</robotBaseFrame>
      <odometrySource>1</odometrySource>
      <publishWheelTF>true</publishWheelTF>
      <publishWheelJointState>true</publishWheelJointState>
    </plugin>
  </gazebo>
  <transmission name="simple_trans">
    <type>transmission_interface/SimpleTransmission</type>
    <joint name="lifter_joint">
      <hardwareInterface>PositionJointInterface</hardwareInterface>
    </joint>
    <actuator name="lifter_motor">
      <mechanicalReduction>50</mechanicalReduction>
      <hardwareInterface>PositionJointInterface</hardwareInterface>
    </actuator>
  </transmission>
  <gazebo>
    <plugin name="gazebo_ros_control" filename="libgazebo_ros_control.so">
      <robotNamespace>/stair_climber</robotNamespace>
    </plugin>
  </gazebo>
  <gazebo reference="lifter_base_imu">
    <gravity>true</gravity>
    <sensor name="imu_sensor" type="imu">
      <always_on>true</always_on>
      <update_rate>100</update_rate>
      <visualize>true</visualize>
      <topic>imu_sensor</topic>
      <plugin filename="libgazebo_ros_imu_sensor.so" name="imu_plugin">
        <topicName>imu</topicName>
        <bodyName>base_link</bodyName>
        <updateRateHZ>10.0</updateRateHZ>
        <gaussianNoise>0.0</gaussianNoise>
        <xyzOffset>0 0 0</xyzOffset>
        <rpyOffset>0 0 0</rpyOffset>
        <frameName>base_link</frameName>
        <initialOrientationAsReference>false</initialOrientationAsReference>
      </plugin>
      <pose>0 0 0 0 0 0</pose>
    </sensor>
  </gazebo>
  <!-- <link name="kinect_rod">
    <inertial>
      <origin xyz="2.945E-06 2.8388E-06 2.5103E-16" rpy="0 0 0" />
      <mass value="0.002763" />
      <inertia ixx="1.4164E-06" ixy="2.5328E-22" ixz="5.0848E-23" iyy="7.0291E-08" iyz="-2.9899E-23" izz="1.4183E-06" />
    </inertial>
    <visual>
      <origin xyz="0 0 0" rpy="0 0 0" />
      <geometry>
        <mesh filename="package://amazon_hackon/models/stair_climber/meshes/kinect_rod.STL" />
      </geometry>
      <material name="">
        <color rgba="0.77255 0.75294 0.73333 1" />
      </material>
    </visual>
    <collision>
      <origin xyz="0 0 0" rpy="0 0 0" />
      <geometry>
        <mesh filename="package://amazon_hackon/models/stair_climber/meshes/kinect_rod.STL" />
      </geometry>
    </collision>
  </link>
  <joint name="kinect_rod_joint" type="fixed">
    <origin xyz="0.32265 0 0.19023" rpy="1.5708 0 0" />
    <parent link="base_link" />
    <child link="kinect_rod" />
    <axis xyz="0 0 0" />
  </joint>
  <link name="rear_proximity">
    <inertial>
      <origin xyz="0.0062452 3.2017E-05 -0.0014786" rpy="0 0 0" />
      <mass value="0.027653" />
      <inertia ixx="2.3096E-05" ixy="7.8475E-12" ixz="-1.1478E-08" iyy="8.4763E-07" iyz="6.099E-09" izz="2.2578E-05" />
    </inertial>
    <visual>
      <origin xyz="0 0 0" rpy="0 0 0" />
      <geometry>
        <mesh filename="package://amazon_hackon/models/stair_climber/meshes/rear_proximity.STL" />
      </geometry>
      <material name="">
        <color rgba="0.75294 0.75294 0.75294 1" />
      </material>
    </visual>
    <collision>
      <origin xyz="0 0 0" rpy="0 0 0" />
      <geometry>
        <mesh filename="package://amazon_hackon/models/stair_climber/meshes/rear_proximity.STL" />
      </geometry>
    </collision>
  </link>
  <joint name="rear_proximity_joint" type="fixed">
    <origin xyz="-0.17875 0.0096015 0.48894" rpy="0 0 1.5708" />
    <parent link="lifter_base" />
    <child link="rear_proximity" />
    <axis xyz="0 0 0" />
  </joint> -->
</robot>
